Workbook
Name NextBookOptions: OFFSET(BookTracker!$O$119,0,0,COUNTA(BookTracker!$O$119:$O$100002),1)
Name TBRBookList: BookTracker!$O$1:$O$43
Name TBRBookTitles: #REF!

Sheet BookTracker
A1: 📚 Book Reading Tracker
A2: 📊 SUMMARY
A3: Metric | B3: Count | C3: Avg Words | D3: Avg Pages | E3: Avg Rating
A4: Total Books Read (All Time) | B4: =COUNTA(TotalRankings!D2:D9998)+COUNTA(TotalRankings!AJ2:AJ9998) -> 131 | C4: =AVERAGE(TotalRankings!H2:H9998) -> 198004.42 | D4: =IFERROR(ROUND(C4/350,0),"-") -> 566 | E4: =IFERROR(ROUND(AVERAGEIF(TotalRankings!$C:$C,">0"),2),"-") -> 7.59
A5: Books Read in 2026 | B5: =COUNTIF('2026BooksRead'!D2:D10000,"?*")+COUNTIF('2026BooksRead'!AJ2:AJ10000,"?*") -> 55 | C5: =AVERAGE('2026BooksRead'!H2:H10000) -> 187284.58 | D5: =IFERROR(ROUND(C5/350,0),"-") -> 535 | E5: =IFERROR(ROUND(AVERAGEIF('2026BooksRead'!$C:$C,">0"),2),"-") -> 7.7
A6: Books Read in 2025 | B6: =COUNTIF('2025BooksRead'!D2:D9999,"?*")+COUNTIF('2025BooksRead'!AJ2:AJ10000,"?*") -> 76 | C6: =AVERAGE('2025BooksRead'!H2:H9999) -> 205640.48 | D6: =IFERROR(ROUND(C6/350,0),"-") -> 588 | E6: =IFERROR(ROUND(AVERAGEIF('2025BooksRead'!$C:$C,">0"),2),"-") -> 7.51
A8: 📖 READING STATUS | B8: Book | C8: Author | D8: Genre | E8: Series | F8: Words | G8: Rank | H8: Score
A9: 📚 Last Read | B9: {=IFERROR(INDEX(TBRFinished!D:D,_xlfn.XMATCH("*",TBRFinished!D2:D10013,2,-1)+1),"None yet")} -> The Martian Chronicles | C9: {=IFERROR(INDEX(TBRFinished!F:F,_xlfn.XMATCH("*",TBRFinished!D2:D10013,2,-1)+1),"")} -> Ray Bradbury | D9: {=IFERROR(INDEX(TBRFinished!E:E,_xlfn.XMATCH("*",TBRFinished!D2:D10013,2,-1)+1),"")} -> Speculative Literary Fiction | E9: {=IFERROR(INDEX(TBRFinished!G:G,_xlfn.XMATCH("*",TBRFinished!D2:D10013,2,-1)+1),"")} -> Standalone | F9: =IF(B9="","",IFERROR(_xlfn.XLOOKUP(B9,TBRFinished!D:D,TBRFinished!H:H),"")) -> 64198 | G9: =COUNTIF(TotalRankings!$C$2:$C$401,">"&H9)+1 -> 93 | H9: =IFERROR(TEXT(_xlfn.XLOOKUP(B9,TotalRankings!D:D,TotalRankings!C:C),"0.00"),"") -> 7.11
A10: 📖 Currently Reading | B10: =ReadNext!B4 -> Endymion | C10: =IF(B10="","",IFERROR(_xlfn.XLOOKUP(B10,Recommendations!D:D,Recommendations!F:F),"")) -> Dan Simmons | D10: =IF(B10="","",IFERROR(_xlfn.XLOOKUP(B10,Recommendations!D:D,Recommendations!E:E),"")) -> Science Fiction (Hard) | E10: =IF(B10="","",IFERROR(_xlfn.XLOOKUP(B10,Recommendations!D:D,Recommendations!G:G),"")) -> Hyperion Cantos | F10: =IF(B10="","",IFERROR(_xlfn.XLOOKUP(B10,Recommendations!D:D,Recommendations!H:H),"")) -> 280000 | G10: =IF(B10="","",IFERROR(_xlfn.XLOOKUP(B10,Recommendations!D:D,Recommendations!A:A),"")) -> 63 | H10: =IF(B10="","",IFERROR(_xlfn.XLOOKUP(B10,Recommendations!D:D,Recommendations!C:C),"")) -> 7.7649269
A11: 📖🔜 Reading Next | B11: =ReadNext!B5 -> The Republic of Thieves | C11: =IF(B11="","",IFERROR(_xlfn.XLOOKUP(B11,Recommendations!D:D,Recommendations!F:F),"")) -> Scott Lynch | D11: =IF(B11="","",IFERROR(_xlfn.XLOOKUP(B11,Recommendations!D:D,Recommendations!E:E),"")) -> Epic Fantasy | E11: =IF(B11="","",IFERROR(_xlfn.XLOOKUP(B11,Recommendations!D:D,Recommendations!G:G),"")) -> Gentleman Bastards | F11: =IF(B11="","",IFERROR(_xlfn.XLOOKUP(B11,Recommendations!D:D,Recommendations!H:H),"")) -> 220000 | G11: =IF(B11="","",IFERROR(_xlfn.XLOOKUP(B11,Recommendations!D:D,Recommendations!A:A),"")) -> 74 | H11: =IF(B11="","",IFERROR(_xlfn.XLOOKUP(B11,Recommendations!D:D,Recommendations!C:C),"")) -> 7.5524151
A13: 🎭 BOOKS BY GENRE (FICTION) | B13: {=SUMPRODUCT((LEN(TotalRankings!E2:E498)>0)*1)} -> 125 | C13: =IFERROR(AVERAGE(TotalRankings!H2:H9998),"-") -> 198004.42 | D13: =IFERROR(ROUND(C13/350,0),"-") -> 566 | E13: =IFERROR(ROUND(AVERAGEIF(TotalRankings!$E:$E,">0""", TotalRankings!$C:$C),2),"-") -> 7.59 | F13: {=SUMPRODUCT((LEN('2025BooksRead'!E2:E499)>0)*1)} -> 73 | G13: =IFERROR(AVERAGE('2025BooksRead'!H2:H9999),"-") -> 205640.48 | H13: =IFERROR(ROUND(G13/350,0),"-") -> 588 | I13: =IFERROR(AVERAGEIF('2025BooksRead'!$E:$E,"<>"&"", '2025BooksRead'!$C:$C),"-") -> 4.6062218 | J13: {=SUMPRODUCT((LEN('2026BooksRead'!E2:E501)>0)*1)} -> 52 | K13: =IFERROR(AVERAGE('2026BooksRead'!H2:H10000),"-") -> 187284.58 | L13: =IFERROR(ROUND(K13/350,0),"-") -> 535 | M13: =IFERROR(ROUND(AVERAGEIF('2026BooksRead'!$C:$C,">0"),2),"-") -> 7.7
A14: Genre | B14: Books (Total) | C14: Avg Words (Total) | D14: Avg Pages (Total) | E14: Avg Rating (Total) | F14: Books (2025) | G14: Avg Words (2025) | H14: Avg Pages (2025) | I14: Avg Rating (2025) | J14: Books (2026) | K14: Avg Words (2026) | L14: Avg Pages (2026) | M14: Avg Rating (2026)
A15: {=_xlfn.SORTBY(_xlfn.UNIQUE(_xlfn._xlws.FILTER(TotalRankings!E2:E498,TotalRankings!E2:E498<>"")),COUNTIF(TotalRankings!E:E,_xlfn.UNIQUE(_xlfn._xlws.FILTER(TotalRankings!E2:E498,TotalRankings!E2:E498<>""))),-1)} -> Epic Fantasy | B15: =IF(A15="","",COUNTIF(TotalRankings!E:E,A15)) -> 53 | C15: =IF(A15="","",IFERROR(AVERAGEIF(TotalRankings!E:E,A15,TotalRankings!H:H),"-")) -> 280242.45 | D15: =IF(A15="","",IFERROR(ROUND(C15/350,0),"-")) -> 801 | E15: =IF(A15="","",IFERROR(ROUND(AVERAGEIF(TotalRankings!$E$2:$E$498,A15,TotalRankings!$C$2:$C$498),2),"-")) -> 8.06 | F15: =IF(A15="","",COUNTIF('2025BooksRead'!E:E,A15)) -> 27 | G15: =IF(A15="","",IFERROR(AVERAGEIF('2025BooksRead'!E:E,A15,'2025BooksRead'!H:H),"-")) -> 309324.07 | H15: =IF(A15="","",IFERROR(ROUND(G15/350,0),"-")) -> 884 | I15: =IF(A15="","",IFERROR(AVERAGEIF('2025BooksRead'!E:E,A15,'2025BooksRead'!C:C),"-")) -> 7.9511176 | J15: =IF(A15="","",COUNTIF('2026BooksRead'!E:E,A15)) -> 26 | K15: =IF(A15="","",IFERROR(AVERAGEIF('2026BooksRead'!E:E,A15,'2026BooksRead'!H:H),"-")) -> 250042.31 | L15: =IF(A15="","",IFERROR(ROUND(K15/350,0),"-")) -> 714 | M15: =IF(A15="","",IFERROR(AVERAGEIF('2026BooksRead'!E:E,A15,'2026BooksRead'!C:C),"-")) -> 8.1819255
A16: Science Fiction (Soft) | B16: =IF(A16="","",COUNTIF(TotalRankings!E:E,A16)) -> 16 | C16: =IF(A16="","",IFERROR(AVERAGEIF(TotalRankings!E:E,A16,TotalRankings!H:H),"-")) -> 211344.06 | D16: =IF(A16="","",IFERROR(ROUND(C16/350,0),"-")) -> 604 | E16: =IF(A16="","",IFERROR(ROUND(AVERAGEIF(TotalRankings!$E$2:$E$498,A16,TotalRankings!$C$2:$C$498),2),"-")) -> 7.46 | F16: =IF(A16="","",COUNTIF('2025BooksRead'!E:E,A16)) -> 13 | G16: =IF(A16="","",IFERROR(AVERAGEIF('2025BooksRead'!E:E,A16,'2025BooksRead'!H:H),"-")) -> 232538.85 | H16: =IF(A16="","",IFERROR(ROUND(G16/350,0),"-")) -> 664 | I16: =IF(A16="","",IFERROR(AVERAGEIF('2025BooksRead'!E:E,A16,'2025BooksRead'!C:C),"-")) -> 7.9801661 | J16: =IF(A16="","",COUNTIF('2026BooksRead'!E:E,A16)) -> 3 | K16: =IF(A16="","",IFERROR(AVERAGEIF('2026BooksRead'!E:E,A16,'2026BooksRead'!H:H),"-")) -> 119500 | L16: =IF(A16="","",IFERROR(ROUND(K16/350,0),"-")) -> 341 | M16: =IF(A16="","",IFERROR(AVERAGEIF('2026BooksRead'!E:E,A16,'2026BooksRead'!C:C),"-")) -> 5.2242853
A17: Science Fiction (Hard) | B17: =IF(A17="","",COUNTIF(TotalRankings!E:E,A17)) -> 14 | C17: =IF(A17="","",IFERROR(AVERAGEIF(TotalRankings!E:E,A17,TotalRankings!H:H),"-")) -> 126071.43 | D17: =IF(A17="","",IFERROR(ROUND(C17/350,0),"-")) -> 360 | E17: =IF(A17="","",IFERROR(ROUND(AVERAGEIF(TotalRankings!$E$2:$E$498,A17,TotalRankings!$C$2:$C$498),2),"-")) -> 7.36 | F17: =IF(A17="","",COUNTIF('2025BooksRead'!E:E,A17)) -> 8 | G17: =IF(A17="","",IFERROR(AVERAGEIF('2025BooksRead'!E:E,A17,'2025BooksRead'!H:H),"-")) -> 120000 | H17: =IF(A17="","",IFERROR(ROUND(G17/350,0),"-")) -> 343 | I17: =IF(A17="","",IFERROR(AVERAGEIF('2025BooksRead'!E:E,A17,'2025BooksRead'!C:C),"-")) -> 7.5175794 | J17: =IF(A17="","",COUNTIF('2026BooksRead'!E:E,A17)) -> 6 | K17: =IF(A17="","",IFERROR(AVERAGEIF('2026BooksRead'!E:E,A17,'2026BooksRead'!H:H),"-")) -> 134166.67 | L17: =IF(A17="","",IFERROR(ROUND(K17/350,0),"-")) -> 383 | M17: =IF(A17="","",IFERROR(AVERAGEIF('2026BooksRead'!E:E,A17,'2026BooksRead'!C:C),"-")) -> 7.1523103
A18: Literary Fantasy | B18: =IF(A18="","",COUNTIF(TotalRankings!E:E,A18)) -> 13 | C18: =IF(A18="","",IFERROR(AVERAGEIF(TotalRankings!E:E,A18,TotalRankings!H:H),"-")) -> 99923.077 | D18: =IF(A18="","",IFERROR(ROUND(C18/350,0),"-")) -> 285 | E18: =IF(A18="","",IFERROR(ROUND(AVERAGEIF(TotalRankings!$E$2:$E$498,A18,TotalRankings!$C$2:$C$498),2),"-")) -> 7.1 | F18: =IF(A18="","",COUNTIF('2025BooksRead'!E:E,A18)) -> 10 | G18: =IF(A18="","",IFERROR(AVERAGEIF('2025BooksRead'!E:E,A18,'2025BooksRead'!H:H),"-")) -> 98900 | H18: =IF(A18="","",IFERROR(ROUND(G18/350,0),"-")) -> 283 | I18: =IF(A18="","",IFERROR(AVERAGEIF('2025BooksRead'!E:E,A18,'2025BooksRead'!C:C),"-")) -> 6.7811056 | J18: =IF(A18="","",COUNTIF('2026BooksRead'!E:E,A18)) -> 3 | K18: =IF(A18="","",IFERROR(AVERAGEIF('2026BooksRead'!E:E,A18,'2026BooksRead'!H:H),"-")) -> 103333.33 | L18: =IF(A18="","",IFERROR(ROUND(K18/350,0),"-")) -> 295 | M18: =IF(A18="","",IFERROR(AVERAGEIF('2026BooksRead'!E:E,A18,'2026BooksRead'!C:C),"-")) -> 8.1419611
A19: Science Fantasy | B19: =IF(A19="","",COUNTIF(TotalRankings!E:E,A19)) -> 11 | C19: =IF(A19="","",IFERROR(AVERAGEIF(TotalRankings!E:E,A19,TotalRankings!H:H),"-")) -> 157727.27 | D19: =IF(A19="","",IFERROR(ROUND(C19/350,0),"-")) -> 451 | E19: =IF(A19="","",IFERROR(ROUND(AVERAGEIF(TotalRankings!$E$2:$E$498,A19,TotalRankings!$C$2:$C$498),2),"-")) -> 6.98 | F19: =IF(A19="","",COUNTIF('2025BooksRead'!E:E,A19)) -> 3 | G19: =IF(A19="","",IFERROR(AVERAGEIF('2025BooksRead'!E:E,A19,'2025BooksRead'!H:H),"-")) -> 120000 | H19: =IF(A19="","",IFERROR(ROUND(G19/350,0),"-")) -> 343 | I19: =IF(A19="","",IFERROR(AVERAGEIF('2025BooksRead'!E:E,A19,'2025BooksRead'!C:C),"-")) -> 5.9568403 | J19: =IF(A19="","",COUNTIF('2026BooksRead'!E:E,A19)) -> 8 | K19: =IF(A19="","",IFERROR(AVERAGEIF('2026BooksRead'!E:E,A19,'2026BooksRead'!H:H),"-")) -> 171875 | L19: =IF(A19="","",IFERROR(ROUND(K19/350,0),"-")) -> 491 | M19: =IF(A19="","",IFERROR(AVERAGEIF('2026BooksRead'!E:E,A19,'2026BooksRead'!C:C),"-")) -> 7.3618932
A20: Literary Fiction | B20: =IF(A20="","",COUNTIF(TotalRankings!E:E,A20)) -> 4 | C20: =IF(A20="","",IFERROR(AVERAGEIF(TotalRankings!E:E,A20,TotalRankings!H:H),"-")) -> 102500 | D20: =IF(A20="","",IFERROR(ROUND(C20/350,0),"-")) -> 293 | E20: =IF(A20="","",IFERROR(ROUND(AVERAGEIF(TotalRankings!$E$2:$E$498,A20,TotalRankings!$C$2:$C$498),2),"-")) -> 6 | F20: =IF(A20="","",COUNTIF('2025BooksRead'!E:E,A20)) -> 4 | G20: =IF(A20="","",IFERROR(AVERAGEIF('2025BooksRead'!E:E,A20,'2025BooksRead'!H:H),"-")) -> 102500 | H20: =IF(A20="","",IFERROR(ROUND(G20/350,0),"-")) -> 293 | I20: =IF(A20="","",IFERROR(AVERAGEIF('2025BooksRead'!E:E,A20,'2025BooksRead'!C:C),"-")) -> 5.99725 | J20: =IF(A20="","",COUNTIF('2026BooksRead'!E:E,A20)) -> 0 | K20: =IF(A20="","",IFERROR(AVERAGEIF('2026BooksRead'!E:E,A20,'2026BooksRead'!H:H),"-")) -> - | L20: =IF(A20="","",IFERROR(ROUND(K20/350,0),"-")) -> - | M20: =IF(A20="","",IFERROR(AVERAGEIF('2026BooksRead'!E:E,A20,'2026BooksRead'!C:C),"-")) -> -
A21: Russian Literature | B21: =IF(A21="","",COUNTIF(TotalRankings!E:E,A21)) -> 3 | C21: =IF(A21="","",IFERROR(AVERAGEIF(TotalRankings!E:E,A21,TotalRankings!H:H),"-")) -> 106000 | D21: =IF(A21="","",IFERROR(ROUND(C21/350,0),"-")) -> 303 | E21: =IF(A21="","",IFERROR(ROUND(AVERAGEIF(TotalRankings!$E$2:$E$498,A21,TotalRankings!$C$2:$C$498),2),"-")) -> 8.23 | F21: =IF(A21="","",COUNTIF('2025BooksRead'!E:E,A21)) -> 1 | G21: =IF(A21="","",IFERROR(AVERAGEIF('2025BooksRead'!E:E,A21,'2025BooksRead'!H:H),"-")) -> 164000 | H21: =IF(A21="","",IFERROR(ROUND(G21/350,0),"-")) -> 469 | I21: =IF(A21="","",IFERROR(AVERAGEIF('2025BooksRead'!E:E,A21,'2025BooksRead'!C:C),"-")) -> 8.5225405 | J21: =IF(A21="","",COUNTIF('2026BooksRead'!E:E,A21)) -> 2 | K21: =IF(A21="","",IFERROR(AVERAGEIF('2026BooksRead'!E:E,A21,'2026BooksRead'!H:H),"-")) -> 77000 | L21: =IF(A21="","",IFERROR(ROUND(K21/350,0),"-")) -> 220 | M21: =IF(A21="","",IFERROR(AVERAGEIF('2026BooksRead'!E:E,A21,'2026BooksRead'!C:C),"-")) -> 8.0847893
A22: Classical Epic | B22: =IF(A22="","",COUNTIF(TotalRankings!E:E,A22)) -> 3 | C22: =IF(A22="","",IFERROR(AVERAGEIF(TotalRankings!E:E,A22,TotalRankings!H:H),"-")) -> 166000 | D22: =IF(A22="","",IFERROR(ROUND(C22/350,0),"-")) -> 474 | E22: =IF(A22="","",IFERROR(ROUND(AVERAGEIF(TotalRankings!$E$2:$E$498,A22,TotalRankings!$C$2:$C$498),2),"-")) -> 7.85 | F22: =IF(A22="","",COUNTIF('2025BooksRead'!E:E,A22)) -> 3 | G22: =IF(A22="","",IFERROR(AVERAGEIF('2025BooksRead'!E:E,A22,'2025BooksRead'!H:H),"-")) -> 166000 | H22: =IF(A22="","",IFERROR(ROUND(G22/350,0),"-")) -> 474 | I22: =IF(A22="","",IFERROR(AVERAGEIF('2025BooksRead'!E:E,A22,'2025BooksRead'!C:C),"-")) -> 7.8485417 | J22: =IF(A22="","",COUNTIF('2026BooksRead'!E:E,A22)) -> 0 | K22: =IF(A22="","",IFERROR(AVERAGEIF('2026BooksRead'!E:E,A22,'2026BooksRead'!H:H),"-")) -> - | L22: =IF(A22="","",IFERROR(ROUND(K22/350,0),"-")) -> - | M22: =IF(A22="","",IFERROR(AVERAGEIF('2026BooksRead'!E:E,A22,'2026BooksRead'!C:C),"-")) -> -
A23: Speculative Literary Fiction | B23: =IF(A23="","",COUNTIF(TotalRankings!E:E,A23)) -> 3 | C23: =IF(A23="","",IFERROR(AVERAGEIF(TotalRankings!E:E,A23,TotalRankings!H:H),"-")) -> 67732.667 | D23: =IF(A23="","",IFERROR(ROUND(C23/350,0),"-")) -> 194 | E23: =IF(A23="","",IFERROR(ROUND(AVERAGEIF(TotalRankings!$E$2:$E$498,A23,TotalRankings!$C$2:$C$498),2),"-")) -> 6.06 | F23: =IF(A23="","",COUNTIF('2025BooksRead'!E:E,A23)) -> 1 | G23: =IF(A23="","",IFERROR(AVERAGEIF('2025BooksRead'!E:E,A23,'2025BooksRead'!H:H),"-")) -> 95000 | H23: =IF(A23="","",IFERROR(ROUND(G23/350,0),"-")) -> 271 | I23: =IF(A23="","",IFERROR(AVERAGEIF('2025BooksRead'!E:E,A23,'2025BooksRead'!C:C),"-")) -> 5.1551912 | J23: =IF(A23="","",COUNTIF('2026BooksRead'!E:E,A23)) -> 2 | K23: =IF(A23="","",IFERROR(AVERAGEIF('2026BooksRead'!E:E,A23,'2026BooksRead'!H:H),"-")) -> 54099 | L23: =IF(A23="","",IFERROR(ROUND(K23/350,0),"-")) -> 155 | M23: =IF(A23="","",IFERROR(AVERAGEIF('2026BooksRead'!E:E,A23,'2026BooksRead'!C:C),"-")) -> 6.5091544
A24: Gothic Fiction | B24: =IF(A24="","",COUNTIF(TotalRankings!E:E,A24)) -> 2 | C24: =IF(A24="","",IFERROR(AVERAGEIF(TotalRankings!E:E,A24,TotalRankings!H:H),"-")) -> 63500 | D24: =IF(A24="","",IFERROR(ROUND(C24/350,0),"-")) -> 181 | E24: =IF(A24="","",IFERROR(ROUND(AVERAGEIF(TotalRankings!$E$2:$E$498,A24,TotalRankings!$C$2:$C$498),2),"-")) -> 8.19 | F24: =IF(A24="","",COUNTIF('2025BooksRead'!E:E,A24)) -> 0 | G24: =IF(A24="","",IFERROR(AVERAGEIF('2025BooksRead'!E:E,A24,'2025BooksRead'!H:H),"-")) -> - | H24: =IF(A24="","",IFERROR(ROUND(G24/350,0),"-")) -> - | I24: =IF(A24="","",IFERROR(AVERAGEIF('2025BooksRead'!E:E,A24,'2025BooksRead'!C:C),"-")) -> - | J24: =IF(A24="","",COUNTIF('2026BooksRead'!E:E,A24)) -> 2 | K24: =IF(A24="","",IFERROR(AVERAGEIF('2026BooksRead'!E:E,A24,'2026BooksRead'!H:H),"-")) -> 63500 | L24: =IF(A24="","",IFERROR(ROUND(K24/350,0),"-")) -> 181 | M24: =IF(A24="","",IFERROR(AVERAGEIF('2026BooksRead'!E:E,A24,'2026BooksRead'!C:C),"-")) -> 8.1871099
A25: Classical Drama | B25: =IF(A25="","",COUNTIF(TotalRankings!E:E,A25)) -> 2 | C25: =IF(A25="","",IFERROR(AVERAGEIF(TotalRankings!E:E,A25,TotalRankings!H:H),"-")) -> 40500 | D25: =IF(A25="","",IFERROR(ROUND(C25/350,0),"-")) -> 116 | E25: =IF(A25="","",IFERROR(ROUND(AVERAGEIF(TotalRankings!$E$2:$E$498,A25,TotalRankings!$C$2:$C$498),2),"-")) -> 7.37 | F25: =IF(A25="","",COUNTIF('2025BooksRead'!E:E,A25)) -> 2 | G25: =IF(A25="","",IFERROR(AVERAGEIF('2025BooksRead'!E:E,A25,'2025BooksRead'!H:H),"-")) -> 40500 | H25: =IF(A25="","",IFERROR(ROUND(G25/350,0),"-")) -> 116 | I25: =IF(A25="","",IFERROR(AVERAGEIF('2025BooksRead'!E:E,A25,'2025BooksRead'!C:C),"-")) -> 7.3694333 | J25: =IF(A25="","",COUNTIF('2026BooksRead'!E:E,A25)) -> 0 | K25: =IF(A25="","",IFERROR(AVERAGEIF('2026BooksRead'!E:E,A25,'2026BooksRead'!H:H),"-")) -> - | L25: =IF(A25="","",IFERROR(ROUND(K25/350,0),"-")) -> - | M25: =IF(A25="","",IFERROR(AVERAGEIF('2026BooksRead'!E:E,A25,'2026BooksRead'!C:C),"-")) -> -
A26: Cyberpunk | B26: =IF(A26="","",COUNTIF(TotalRankings!E:E,A26)) -> 1 | C26: =IF(A26="","",IFERROR(AVERAGEIF(TotalRankings!E:E,A26,TotalRankings!H:H),"-")) -> 80000 | D26: =IF(A26="","",IFERROR(ROUND(C26/350,0),"-")) -> 229 | E26: =IF(A26="","",IFERROR(ROUND(AVERAGEIF(TotalRankings!$E$2:$E$498,A26,TotalRankings!$C$2:$C$498),2),"-")) -> 7.94 | F26: =IF(A26="","",COUNTIF('2025BooksRead'!E:E,A26)) -> 1 | G26: =IF(A26="","",IFERROR(AVERAGEIF('2025BooksRead'!E:E,A26,'2025BooksRead'!H:H),"-")) -> 80000 | H26: =IF(A26="","",IFERROR(ROUND(G26/350,0),"-")) -> 229 | I26: =IF(A26="","",IFERROR(AVERAGEIF('2025BooksRead'!E:E,A26,'2025BooksRead'!C:C),"-")) -> 7.9446272 | J26: =IF(A26="","",COUNTIF('2026BooksRead'!E:E,A26)) -> 0 | K26: =IF(A26="","",IFERROR(AVERAGEIF('2026BooksRead'!E:E,A26,'2026BooksRead'!H:H),"-")) -> - | L26: =IF(A26="","",IFERROR(ROUND(K26/350,0),"-")) -> - | M26: =IF(A26="","",IFERROR(AVERAGEIF('2026BooksRead'!E:E,A26,'2026BooksRead'!C:C),"-")) -> -
A28: ✍️ BOOKS BY AUTHOR (FICTION) | B28: {=SUMPRODUCT((LEN(TotalRankings!F2:F498)>0)*1)} -> 125 | C28: =AVERAGE(TotalRankings!H2:H113) -> 210268.33 | D28: =IFERROR(ROUND(C28/350,0),"-") -> 601 | E28: =IFERROR(ROUND(AVERAGEIF(TotalRankings!$E:$E,">0""", TotalRankings!$C:$C),2),"-") -> 7.59 | F28: {=SUMPRODUCT((LEN('2025BooksRead'!F2:F499)>0)*1)} -> 73 | G28: =AVERAGE('2025BooksRead'!H2:H120) -> 205640.48 | H28: =IFERROR(ROUND(G28/350,0),"-") -> 588 | I28: =IFERROR(ROUND(AVERAGE('2025BooksRead'!C2:C120),2),"-") -> 4.61 | J28: {=SUMPRODUCT((LEN('2026BooksRead'!F2:F501)>0)*1)} -> 52 | K28: =AVERAGE('2026BooksRead'!H2:H40) -> 198541.03 | L28: =IFERROR(ROUND(K28/350,0),"-") -> 567 | M28: =IFERROR(ROUND(AVERAGEIF('2026BooksRead'!$C:$C,">0"),2),"-") -> 7.7
A29: Authors | B29: Books (Total) | C29: Avg Words (Total) | D29: Avg Pages (Total) | E29: Avg Rating (Total) | F29: Books (2025) | G29: Avg Words (2025) | H29: Avg Pages (2025) | I29: Avg Rating (2025) | J29: Books (2026) | K29: Avg Words (2026) | L29: Avg Pages (2026) | M29: Avg Rating (2026)
A30: {=_xlfn.SORTBY(_xlfn.UNIQUE(_xlfn._xlws.FILTER(TotalRankings!F2:F498,TotalRankings!F2:F498<>"")),COUNTIF(TotalRankings!F:F,_xlfn.UNIQUE(_xlfn._xlws.FILTER(TotalRankings!F2:F498,TotalRankings!F2:F498<>""))),-1)} -> Brandon Sanderson | B30: =IF(A30="","",COUNTIF(TotalRankings!F:F,A30)) -> 18 | C30: =IF(A30="","",IFERROR(AVERAGEIF(TotalRankings!F:F,A30,TotalRankings!H:H),"-")) -> 246833.33 | D30: =IF(A30="","",IFERROR(ROUND(C30/350,0),"-")) -> 705 | E30: =IF(A30="","",IFERROR(ROUND(AVERAGEIF(TotalRankings!$F$2:$F$498,A30,TotalRankings!$C$2:$C$498),2),"-")) -> 7.32 | F30: =IF(A30="","",COUNTIF('2025BooksRead'!F:F,A30)) -> 18 | G30: =IF(A30="","",IFERROR(AVERAGEIF('2025BooksRead'!F:F,A30,'2025BooksRead'!H:H),"-")) -> 246833.33 | H30: =IF(A30="","",IFERROR(ROUND(G30/350,0),"-")) -> 705 | I30: =IF(A30="","",IFERROR(AVERAGEIF('2025BooksRead'!F:F,A30,'2025BooksRead'!C:C),"-")) -> 7.3179113 | J30: =IF(A30="","",COUNTIF('2026BooksRead'!F:F,A30)) -> 0 | K30: =IF(A30="","",IFERROR(AVERAGEIF('2026BooksRead'!F:F,A30,'2026BooksRead'!H:H),"-")) -> - | L30: =IF(A30="","",IFERROR(ROUND(K30/350,0),"-")) -> - | M30: =IF(A30="","",IFERROR(AVERAGEIF('2026BooksRead'!F:F,A30,'2026BooksRead'!C:C),"-")) -> -
A31: Robert Jordan | B31: =IF(A31="","",COUNTIF(TotalRankings!F:F,A31)) -> 12 | C31: =IF(A31="","",IFERROR(AVERAGEIF(TotalRankings!F:F,A31,TotalRankings!H:H),"-")) -> 280916.67 | D31: =IF(A31="","",IFERROR(ROUND(C31/350,0),"-")) -> 803 | E31: =IF(A31="","",IFERROR(ROUND(AVERAGEIF(TotalRankings!$F$2:$F$498,A31,TotalRankings!$C$2:$C$498),2),"-")) -> 8.13 | F31: =IF(A31="","",COUNTIF('2025BooksRead'!F:F,A31)) -> 12 | G31: =IF(A31="","",IFERROR(AVERAGEIF('2025BooksRead'!F:F,A31,'2025BooksRead'!H:H),"-")) -> 280916.67 | H31: =IF(A31="","",IFERROR(ROUND(G31/350,0),"-")) -> 803 | I31: =IF(A31="","",IFERROR(AVERAGEIF('2025BooksRead'!F:F,A31,'2025BooksRead'!C:C),"-")) -> 8.1250532 | J31: =IF(A31="","",COUNTIF('2026BooksRead'!F:F,A31)) -> 0 | K31: =IF(A31="","",IFERROR(AVERAGEIF('2026BooksRead'!F:F,A31,'2026BooksRead'!H:H),"-")) -> - | L31: =IF(A31="","",IFERROR(ROUND(K31/350,0),"-")) -> - | M31: =IF(A31="","",IFERROR(AVERAGEIF('2026BooksRead'!F:F,A31,'2026BooksRead'!C:C),"-")) -> -
A32: Steven Erikson | B32: =IF(A32="","",COUNTIF(TotalRankings!F:F,A32)) -> 10 | C32: =IF(A32="","",IFERROR(AVERAGEIF(TotalRankings!F:F,A32,TotalRankings!H:H),"-")) -> 329300 | D32: =IF(A32="","",IFERROR(ROUND(C32/350,0),"-")) -> 941 | E32: =IF(A32="","",IFERROR(ROUND(AVERAGEIF(TotalRankings!$F$2:$F$498,A32,TotalRankings!$C$2:$C$498),2),"-")) -> 9.01 | F32: =IF(A32="","",COUNTIF('2025BooksRead'!F:F,A32)) -> 0 | G32: =IF(A32="","",IFERROR(AVERAGEIF('2025BooksRead'!F:F,A32,'2025BooksRead'!H:H),"-")) -> - | H32: =IF(A32="","",IFERROR(ROUND(G32/350,0),"-")) -> - | I32: =IF(A32="","",IFERROR(AVERAGEIF('2025BooksRead'!F:F,A32,'2025BooksRead'!C:C),"-")) -> - | J32: =IF(A32="","",COUNTIF('2026BooksRead'!F:F,A32)) -> 10 | K32: =IF(A32="","",IFERROR(AVERAGEIF('2026BooksRead'!F:F,A32,'2026BooksRead'!H:H),"-")) -> 329300 | L32: =IF(A32="","",IFERROR(ROUND(K32/350,0),"-")) -> 941 | M32: =IF(A32="","",IFERROR(AVERAGEIF('2026BooksRead'!F:F,A32,'2026BooksRead'!C:C),"-")) -> 9.0081591
A33: Matt Dinniman | B33: =IF(A33="","",COUNTIF(TotalRankings!F:F,A33)) -> 8 | C33: =IF(A33="","",IFERROR(AVERAGEIF(TotalRankings!F:F,A33,TotalRankings!H:H),"-")) -> 171875 | D33: =IF(A33="","",IFERROR(ROUND(C33/350,0),"-")) -> 491 | E33: =IF(A33="","",IFERROR(ROUND(AVERAGEIF(TotalRankings!$F$2:$F$498,A33,TotalRankings!$C$2:$C$498),2),"-")) -> 7.36 | F33: =IF(A33="","",COUNTIF('2025BooksRead'!F:F,A33)) -> 0 | G33: =IF(A33="","",IFERROR(AVERAGEIF('2025BooksRead'!F:F,A33,'2025BooksRead'!H:H),"-")) -> - | H33: =IF(A33="","",IFERROR(ROUND(G33/350,0),"-")) -> - | I33: =IF(A33="","",IFERROR(AVERAGEIF('2025BooksRead'!F:F,A33,'2025BooksRead'!C:C),"-")) -> - | J33: =IF(A33="","",COUNTIF('2026BooksRead'!F:F,A33)) -> 8 | K33: =IF(A33="","",IFERROR(AVERAGEIF('2026BooksRead'!F:F,A33,'2026BooksRead'!H:H),"-")) -> 171875 | L33: =IF(A33="","",IFERROR(ROUND(K33/350,0),"-")) -> 491 | M33: =IF(A33="","",IFERROR(AVERAGEIF('2026BooksRead'!F:F,A33,'2026BooksRead'!C:C),"-")) -> 7.3618932
A34: Orson Scott Card | B34: =IF(A34="","",COUNTIF(TotalRankings!F:F,A34)) -> 7 | C34: =IF(A34="","",IFERROR(AVERAGEIF(TotalRankings!F:F,A34,TotalRankings!H:H),"-")) -> 121857.14 | D34: =IF(A34="","",IFERROR(ROUND(C34/350,0),"-")) -> 348 | E34: =IF(A34="","",IFERROR(ROUND(AVERAGEIF(TotalRankings!$F$2:$F$498,A34,TotalRankings!$C$2:$C$498),2),"-")) -> 6.88 | F34: =IF(A34="","",COUNTIF('2025BooksRead'!F:F,A34)) -> 6 | G34: =IF(A34="","",IFERROR(AVERAGEIF('2025BooksRead'!F:F,A34,'2025BooksRead'!H:H),"-")) -> 125500 | H34: =IF(A34="","",IFERROR(ROUND(G34/350,0),"-")) -> 359 | I34: =IF(A34="","",IFERROR(AVERAGEIF('2025BooksRead'!F:F,A34,'2025BooksRead'!C:C),"-")) -> 7.6445399 | J34: =IF(A34="","",COUNTIF('2026BooksRead'!F:F,A34)) -> 1 | K34: =IF(A34="","",IFERROR(AVERAGEIF('2026BooksRead'!F:F,A34,'2026BooksRead'!H:H),"-")) -> 100000 | L34: =IF(A34="","",IFERROR(ROUND(K34/350,0),"-")) -> 286 | M34: =IF(A34="","",IFERROR(AVERAGEIF('2026BooksRead'!F:F,A34,'2026BooksRead'!C:C),"-")) -> 2.2966095
A35: Christopher Ruocchio | B35: =IF(A35="","",COUNTIF(TotalRankings!F:F,A35)) -> 7 | C35: =IF(A35="","",IFERROR(AVERAGEIF(TotalRankings!F:F,A35,TotalRankings!H:H),"-")) -> 260571.43 | D35: =IF(A35="","",IFERROR(ROUND(C35/350,0),"-")) -> 744 | E35: =IF(A35="","",IFERROR(ROUND(AVERAGEIF(TotalRankings!$F$2:$F$498,A35,TotalRankings!$C$2:$C$498),2),"-")) -> 7.79 | F35: =IF(A35="","",COUNTIF('2025BooksRead'!F:F,A35)) -> 7 | G35: =IF(A35="","",IFERROR(AVERAGEIF('2025BooksRead'!F:F,A35,'2025BooksRead'!H:H),"-")) -> 260571.43 | H35: =IF(A35="","",IFERROR(ROUND(G35/350,0),"-")) -> 744 | I35: =IF(A35="","",IFERROR(AVERAGEIF('2025BooksRead'!F:F,A35,'2025BooksRead'!C:C),"-")) -> 7.794659 | J35: =IF(A35="","",COUNTIF('2026BooksRead'!F:F,A35)) -> 0 | K35: =IF(A35="","",IFERROR(AVERAGEIF('2026BooksRead'!F:F,A35,'2026BooksRead'!H:H),"-")) -> - | L35: =IF(A35="","",IFERROR(ROUND(K35/350,0),"-")) -> - | M35: =IF(A35="","",IFERROR(AVERAGEIF('2026BooksRead'!F:F,A35,'2026BooksRead'!C:C),"-")) -> -
A36: Joe Abercrombie | B36: =IF(A36="","",COUNTIF(TotalRankings!F:F,A36)) -> 6 | C36: =IF(A36="","",IFERROR(AVERAGEIF(TotalRankings!F:F,A36,TotalRankings!H:H),"-")) -> 204433.33 | D36: =IF(A36="","",IFERROR(ROUND(C36/350,0),"-")) -> 584 | E36: =IF(A36="","",IFERROR(ROUND(AVERAGEIF(TotalRankings!$F$2:$F$498,A36,TotalRankings!$C$2:$C$498),2),"-")) -> 8.05 | F36: =IF(A36="","",COUNTIF('2025BooksRead'!F:F,A36)) -> 0 | G36: =IF(A36="","",IFERROR(AVERAGEIF('2025BooksRead'!F:F,A36,'2025BooksRead'!H:H),"-")) -> - | H36: =IF(A36="","",IFERROR(ROUND(G36/350,0),"-")) -> - | I36: =IF(A36="","",IFERROR(AVERAGEIF('2025BooksRead'!F:F,A36,'2025BooksRead'!C:C),"-")) -> - | J36: =IF(A36="","",COUNTIF('2026BooksRead'!F:F,A36)) -> 6 | K36: =IF(A36="","",IFERROR(AVERAGEIF('2026BooksRead'!F:F,A36,'2026BooksRead'!H:H),"-")) -> 204433.33 | L36: =IF(A36="","",IFERROR(ROUND(K36/350,0),"-")) -> 584 | M36: =IF(A36="","",IFERROR(AVERAGEIF('2026BooksRead'!F:F,A36,'2026BooksRead'!C:C),"-")) -> 8.045503
A37: Pierce Brown | B37: =IF(A37="","",COUNTIF(TotalRankings!F:F,A37)) -> 6 | C37: =IF(A37="","",IFERROR(AVERAGEIF(TotalRankings!F:F,A37,TotalRankings!H:H),"-")) -> 199834.17 | D37: =IF(A37="","",IFERROR(ROUND(C37/350,0),"-")) -> 571 | E37: =IF(A37="","",IFERROR(ROUND(AVERAGEIF(TotalRankings!$F$2:$F$498,A37,TotalRankings!$C$2:$C$498),2),"-")) -> 8.2 | F37: =IF(A37="","",COUNTIF('2025BooksRead'!F:F,A37)) -> 6 | G37: =IF(A37="","",IFERROR(AVERAGEIF('2025BooksRead'!F:F,A37,'2025BooksRead'!H:H),"-")) -> 199834.17 | H37: =IF(A37="","",IFERROR(ROUND(G37/350,0),"-")) -> 571 | I37: =IF(A37="","",IFERROR(AVERAGEIF('2025BooksRead'!F:F,A37,'2025BooksRead'!C:C),"-")) -> 8.1965909 | J37: =IF(A37="","",COUNTIF('2026BooksRead'!F:F,A37)) -> 0 | K37: =IF(A37="","",IFERROR(AVERAGEIF('2026BooksRead'!F:F,A37,'2026BooksRead'!H:H),"-")) -> - | L37: =IF(A37="","",IFERROR(ROUND(K37/350,0),"-")) -> - | M37: =IF(A37="","",IFERROR(AVERAGEIF('2026BooksRead'!F:F,A37,'2026BooksRead'!C:C),"-")) -> -
A38: J.R.R. Tolkien | B38: =IF(A38="","",COUNTIF(TotalRankings!F:F,A38)) -> 4 | C38: =IF(A38="","",IFERROR(AVERAGEIF(TotalRankings!F:F,A38,TotalRankings!H:H),"-")) -> 138000 | D38: =IF(A38="","",IFERROR(ROUND(C38/350,0),"-")) -> 394 | E38: =IF(A38="","",IFERROR(ROUND(AVERAGEIF(TotalRankings!$F$2:$F$498,A38,TotalRankings!$C$2:$C$498),2),"-")) -> 8.26 | F38: =IF(A38="","",COUNTIF('2025BooksRead'!F:F,A38)) -> 0 | G38: =IF(A38="","",IFERROR(AVERAGEIF('2025BooksRead'!F:F,A38,'2025BooksRead'!H:H),"-")) -> - | H38: =IF(A38="","",IFERROR(ROUND(G38/350,0),"-")) -> - | I38: =IF(A38="","",IFERROR(AVERAGEIF('2025BooksRead'!F:F,A38,'2025BooksRead'!C:C),"-")) -> - | J38: =IF(A38="","",COUNTIF('2026BooksRead'!F:F,A38)) -> 4 | K38: =IF(A38="","",IFERROR(AVERAGEIF('2026BooksRead'!F:F,A38,'2026BooksRead'!H:H),"-")) -> 138000 | L38: =IF(A38="","",IFERROR(ROUND(K38/350,0),"-")) -> 394 | M38: =IF(A38="","",IFERROR(AVERAGEIF('2026BooksRead'!F:F,A38,'2026BooksRead'!C:C),"-")) -> 8.2589387
A39: Tad Williams | B39: =IF(A39="","",COUNTIF(TotalRankings!F:F,A39)) -> 3 | C39: =IF(A39="","",IFERROR(AVERAGEIF(TotalRankings!F:F,A39,TotalRankings!H:H),"-")) -> 296916.67 | D39: =IF(A39="","",IFERROR(ROUND(C39/350,0),"-")) -> 848 | E39: =IF(A39="","",IFERROR(ROUND(AVERAGEIF(TotalRankings!$F$2:$F$498,A39,TotalRankings!$C$2:$C$498),2),"-")) -> 5.81 | F39: =IF(A39="","",COUNTIF('2025BooksRead'!F:F,A39)) -> 2 | G39: =IF(A39="","",IFERROR(AVERAGEIF('2025BooksRead'!F:F,A39,'2025BooksRead'!H:H),"-")) -> 185375 | H39: =IF(A39="","",IFERROR(ROUND(G39/350,0),"-")) -> 530 | I39: =IF(A39="","",IFERROR(AVERAGEIF('2025BooksRead'!F:F,A39,'2025BooksRead'!C:C),"-")) -> 5.6161373 | J39: =IF(A39="","",COUNTIF('2026BooksRead'!F:F,A39)) -> 1 | K39: =IF(A39="","",IFERROR(AVERAGEIF('2026BooksRead'!F:F,A39,'2026BooksRead'!H:H),"-")) -> 520000 | L39: =IF(A39="","",IFERROR(ROUND(K39/350,0),"-")) -> 1486 | M39: =IF(A39="","",IFERROR(AVERAGEIF('2026BooksRead'!F:F,A39,'2026BooksRead'!C:C),"-")) -> 6.2030794
A40: Timothy Zahn | B40: =IF(A40="","",COUNTIF(TotalRankings!F:F,A40)) -> 3 | C40: =IF(A40="","",IFERROR(AVERAGEIF(TotalRankings!F:F,A40,TotalRankings!H:H),"-")) -> 120000 | D40: =IF(A40="","",IFERROR(ROUND(C40/350,0),"-")) -> 343 | E40: =IF(A40="","",IFERROR(ROUND(AVERAGEIF(TotalRankings!$F$2:$F$498,A40,TotalRankings!$C$2:$C$498),2),"-")) -> 5.96 | F40: =IF(A40="","",COUNTIF('2025BooksRead'!F:F,A40)) -> 3 | G40: =IF(A40="","",IFERROR(AVERAGEIF('2025BooksRead'!F:F,A40,'2025BooksRead'!H:H),"-")) -> 120000 | H40: =IF(A40="","",IFERROR(ROUND(G40/350,0),"-")) -> 343 | I40: =IF(A40="","",IFERROR(AVERAGEIF('2025BooksRead'!F:F,A40,'2025BooksRead'!C:C),"-")) -> 5.9568403 | J40: =IF(A40="","",COUNTIF('2026BooksRead'!F:F,A40)) -> 0 | K40: =IF(A40="","",IFERROR(AVERAGEIF('2026BooksRead'!F:F,A40,'2026BooksRead'!H:H),"-")) -> - | L40: =IF(A40="","",IFERROR(ROUND(K40/350,0),"-")) -> - | M40: =IF(A40="","",IFERROR(AVERAGEIF('2026BooksRead'!F:F,A40,'2026BooksRead'!C:C),"-")) -> -
A41: Dan Simmons | B41: =IF(A41="","",COUNTIF(TotalRankings!F:F,A41)) -> 2 | C41: =IF(A41="","",IFERROR(AVERAGEIF(TotalRankings!F:F,A41,TotalRankings!H:H),"-")) -> 235000 | D41: =IF(A41="","",IFERROR(ROUND(C41/350,0),"-")) -> 671 | E41: =IF(A41="","",IFERROR(ROUND(AVERAGEIF(TotalRankings!$F$2:$F$498,A41,TotalRankings!$C$2:$C$498),2),"-")) -> 9.26 | F41: =IF(A41="","",COUNTIF('2025BooksRead'!F:F,A41)) -> 0 | G41: =IF(A41="","",IFERROR(AVERAGEIF('2025BooksRead'!F:F,A41,'2025BooksRead'!H:H),"-")) -> - | H41: =IF(A41="","",IFERROR(ROUND(G41/350,0),"-")) -> - | I41: =IF(A41="","",IFERROR(AVERAGEIF('2025BooksRead'!F:F,A41,'2025BooksRead'!C:C),"-")) -> - | J41: =IF(A41="","",COUNTIF('2026BooksRead'!F:F,A41)) -> 2 | K41: =IF(A41="","",IFERROR(AVERAGEIF('2026BooksRead'!F:F,A41,'2026BooksRead'!H:H),"-")) -> 235000 | L41: =IF(A41="","",IFERROR(ROUND(K41/350,0),"-")) -> 671 | M41: =IF(A41="","",IFERROR(AVERAGEIF('2026BooksRead'!F:F,A41,'2026BooksRead'!C:C),"-")) -> 9.2649405
A42: Michael Ende | B42: =IF(A42="","",COUNTIF(TotalRankings!F:F,A42)) -> 2 | C42: =IF(A42="","",IFERROR(AVERAGEIF(TotalRankings!F:F,A42,TotalRankings!H:H),"-")) -> 105500 | D42: =IF(A42="","",IFERROR(ROUND(C42/350,0),"-")) -> 301 | E42: =IF(A42="","",IFERROR(ROUND(AVERAGEIF(TotalRankings!$F$2:$F$498,A42,TotalRankings!$C$2:$C$498),2),"-")) -> 8.66 | F42: =IF(A42="","",COUNTIF('2025BooksRead'!F:F,A42)) -> 1 | G42: =IF(A42="","",IFERROR(AVERAGEIF('2025BooksRead'!F:F,A42,'2025BooksRead'!H:H),"-")) -> 111000 | H42: =IF(A42="","",IFERROR(ROUND(G42/350,0),"-")) -> 317 | I42: =IF(A42="","",IFERROR(AVERAGEIF('2025BooksRead'!F:F,A42,'2025BooksRead'!C:C),"-")) -> 9.2712056 | J42: =IF(A42="","",COUNTIF('2026BooksRead'!F:F,A42)) -> 1 | K42: =IF(A42="","",IFERROR(AVERAGEIF('2026BooksRead'!F:F,A42,'2026BooksRead'!H:H),"-")) -> 100000 | L42: =IF(A42="","",IFERROR(ROUND(K42/350,0),"-")) -> 286 | M42: =IF(A42="","",IFERROR(AVERAGEIF('2026BooksRead'!F:F,A42,'2026BooksRead'!C:C),"-")) -> 8.04125
... A73: William Kennedy | B73: =IF(A73="","",COUNTIF(TotalRankings!F:F,A73)) -> 1 | C73: =IF(A73="","",IFERROR(AVERAGEIF(TotalRankings!F:F,A73,TotalRankings!H:H),"-")) -> 57000 | D73: =IF(A73="","",IFERROR(ROUND(C73/350,0),"-")) -> 163 | E73: =IF(A73="","",IFERROR(ROUND(AVERAGEIF(TotalRankings!$F$2:$F$498,A73,TotalRankings!$C$2:$C$498),2),"-")) -> 4.78 | F73: =IF(A73="","",COUNTIF('2025BooksRead'!F:F,A73)) -> 1 | G73: =IF(A73="","",IFERROR(AVERAGEIF('2025BooksRead'!F:F,A73,'2025BooksRead'!H:H),"-")) -> 57000 | H73: =IF(A73="","",IFERROR(ROUND(G73/350,0),"-")) -> 163 | I73: =IF(A73="","",IFERROR(AVERAGEIF('2025BooksRead'!F:F,A73,'2025BooksRead'!C:C),"-")) -> 4.7791 | J73: =IF(A73="","",COUNTIF('2026BooksRead'!F:F,A73)) -> 0 | K73: =IF(A73="","",IFERROR(AVERAGEIF('2026BooksRead'!F:F,A73,'2026BooksRead'!H:H),"-")) -> - | L73: =IF(A73="","",IFERROR(ROUND(K73/350,0),"-")) -> - | M73: =IF(A73="","",IFERROR(AVERAGEIF('2026BooksRead'!F:F,A73,'2026BooksRead'!C:C),"-")) -> -
...

Sheet ReadNext
A1: MY TO-READ QUEUE | P1: Master Queue (edit here) | AL1: notDoneRecRow (helper)
A2: Series: | N2: notDoneRow (helper) | O2: seriesList (helper) | P2: Red Seas Under Red Skies | AL2: {=IF(INDEX(Recommendations!$D:$D,ROW())="","",IF(INDEX(Recommendations!$AJ:$AJ,ROW())=TRUE,"",ROW()))} -> 2
A3: # | B3: Book (pick from dropdown) | C3: Pred. Score | D3: Rank | E3: Genre | F3: Series | G3: Words | H3: Done? | I3: Auto-Done | N3: {=IF(INDEX($P:$P,ROW()-1)="","",IF(OR(IFERROR(_xlfn.XLOOKUP(INDEX($P:$P,ROW()-1),Recommendations!$D:$D,Recommendations!$AJ:$AJ),FALSE)=TRUE,INDEX($P:$P,ROW()-1)=BookTracker!$B$9),"",ROW()-1))} | O3: {=IFERROR(_xlfn._xlws.SORT(_xlfn.UNIQUE(_xlfn._xlws.FILTER(Recommendations!$G$2:$G$1086,(Recommendations!$G$2:$G$1086<>"")*(Recommendations!$G$2:$G$1086<>"Standalone")*(Recommendations!$AJ$2:$AJ$1086<>TRUE)))),"")} -> A Song of Ice and Fire | P3: Endymion | AL3: {=IF(INDEX(Recommendations!$D:$D,ROW())="","",IF(INDEX(Recommendations!$AJ:$AJ,ROW())=TRUE,"",ROW()))} -> 3
A4: Reading 1 | B4: {=IF(TRIM($B$2)<>"",IFERROR(INDEX(_xlfn._xlws.FILTER(Recommendations!$D$2:$D$1086,(Recommendations!$G$2:$G$1086=TRIM($B$2))*(Recommendations!$AJ$2:$AJ$1086<>TRUE)*(Recommendations!$D$2:$D$1086<>BookTracker!$B$9)),ROW()-3),""),IFERROR(INDEX($P:$P,SMALL($N$3:$N$102,ROW()-3)),""))} -> Endymion | C4: =IF($B4="","",IFERROR(_xlfn.XLOOKUP($B4,Recommendations!$D:$D,Recommendations!$C:$C),"")) -> 7.7649269 | D4: =IF($B4="","",IFERROR(_xlfn.XLOOKUP($B4,Recommendations!$D:$D,Recommendations!$A:$A),"")) -> 63 | E4: =IF($B4="","",IFERROR(_xlfn.XLOOKUP($B4,Recommendations!$D:$D,Recommendations!$E:$E),"")) -> Science Fiction (Hard) | F4: =IF($B4="","",IFERROR(_xlfn.XLOOKUP($B4,Recommendations!$D:$D,Recommendations!$G:$G),"")) -> Hyperion Cantos | G4: =IF($B4="","",IFERROR(_xlfn.XLOOKUP($B4,Recommendations!$D:$D,Recommendations!$H:$H),"")) -> 280000 | H4: =IF($B4="","",IFERROR(_xlfn.XLOOKUP($B4,Recommendations!$D:$D,Recommendations!$AJ:$AJ),FALSE)) -> FALSE | I4: =IF($B4="",FALSE,OR($H4=TRUE,$B4=BookTracker!$B$9)) -> FALSE | N4: {=IF(INDEX($P:$P,ROW()-1)="","",IF(OR(IFERROR(_xlfn.XLOOKUP(INDEX($P:$P,ROW()-1),Recommendations!$D:$D,Recommendations!$AJ:$AJ),FALSE)=TRUE,INDEX($P:$P,ROW()-1)=BookTracker!$B$9),"",ROW()-1))} -> 3 | O4: Aubrey-Maturin | P4: The Republic of Thieves | AL4: {=IF(INDEX(Recommendations!$D:$D,ROW())="","",IF(INDEX(Recommendations!$AJ:$AJ,ROW())=TRUE,"",ROW()))} -> 4
A5: =1 -> 1 | B5: {=IF(TRIM($B$2)<>"",IFERROR(INDEX(_xlfn._xlws.FILTER(Recommendations!$D$2:$D$1086,(Recommendations!$G$2:$G$1086=TRIM($B$2))*(Recommendations!$AJ$2:$AJ$1086<>TRUE)*(Recommendations!$D$2:$D$1086<>BookTracker!$B$9)),ROW()-3),""),IFERROR(INDEX($P:$P,SMALL($N$3:$N$102,ROW()-3)),""))} -> The Republic of Thieves | C5: =IF($B5="","",IFERROR(_xlfn.XLOOKUP($B5,Recommendations!$D:$D,Recommendations!$C:$C),"")) -> 7.5524151 | D5: =IF($B5="","",IFERROR(_xlfn.XLOOKUP($B5,Recommendations!$D:$D,Recommendations!$A:$A),"")) -> 74 | E5: =IF($B5="","",IFERROR(_xlfn.XLOOKUP($B5,Recommendations!$D:$D,Recommendations!$E:$E),"")) -> Epic Fantasy | F5: =IF($B5="","",IFERROR(_xlfn.XLOOKUP($B5,Recommendations!$D:$D,Recommendations!$G:$G),"")) -> Gentleman Bastards | G5: =IF($B5="","",IFERROR(_xlfn.XLOOKUP($B5,Recommendations!$D:$D,Recommendations!$H:$H),"")) -> 220000 | H5: =IF($B5="","",IFERROR(_xlfn.XLOOKUP($B5,Recommendations!$D:$D,Recommendations!$AJ:$AJ),FALSE)) -> FALSE | I5: =IF($B5="",FALSE,OR($H5=TRUE,$B5=BookTracker!$B$9)) -> FALSE | N5: {=IF(INDEX($P:$P,ROW()-1)="","",IF(OR(IFERROR(_xlfn.XLOOKUP(INDEX($P:$P,ROW()-1),Recommendations!$D:$D,Recommendations!$AJ:$AJ),FALSE)=TRUE,INDEX($P:$P,ROW()-1)=BookTracker!$B$9),"",ROW()-1))} -> 4 | O5: Blacktongue | P5: The Rise of Endymion | AL5: {=IF(INDEX(Recommendations!$D:$D,ROW())="","",IF(INDEX(Recommendations!$AJ:$AJ,ROW())=TRUE,"",ROW()))} -> 5
A6: =2 -> 2 | B6: {=IF(TRIM($B$2)<>"",IFERROR(INDEX(_xlfn._xlws.FILTER(Recommendations!$D$2:$D$1086,(Recommendations!$G$2:$G$1086=TRIM($B$2))*(Recommendations!$AJ$2:$AJ$1086<>TRUE)*(Recommendations!$D$2:$D$1086<>BookTracker!$B$9)),ROW()-3),""),IFERROR(INDEX($P:$P,SMALL($N$3:$N$102,ROW()-3)),""))} -> The Rise of Endymion | C6: =IF($B6="","",IFERROR(_xlfn.XLOOKUP($B6,Recommendations!$D:$D,Recommendations!$C:$C),"")) -> 7.9320563 | D6: =IF($B6="","",IFERROR(_xlfn.XLOOKUP($B6,Recommendations!$D:$D,Recommendations!$A:$A),"")) -> 52 | E6: =IF($B6="","",IFERROR(_xlfn.XLOOKUP($B6,Recommendations!$D:$D,Recommendations!$E:$E),"")) -> Science Fiction (Hard) | F6: =IF($B6="","",IFERROR(_xlfn.XLOOKUP($B6,Recommendations!$D:$D,Recommendations!$G:$G),"")) -> Hyperion Cantos | G6: =IF($B6="","",IFERROR(_xlfn.XLOOKUP($B6,Recommendations!$D:$D,Recommendations!$H:$H),"")) -> 420000 | H6: =IF($B6="","",IFERROR(_xlfn.XLOOKUP($B6,Recommendations!$D:$D,Recommendations!$AJ:$AJ),FALSE)) -> FALSE | I6: =IF($B6="",FALSE,OR($H6=TRUE,$B6=BookTracker!$B$9)) -> FALSE | N6: {=IF(INDEX($P:$P,ROW()-1)="","",IF(OR(IFERROR(_xlfn.XLOOKUP(INDEX($P:$P,ROW()-1),Recommendations!$D:$D,Recommendations!$AJ:$AJ),FALSE)=TRUE,INDEX($P:$P,ROW()-1)=BookTracker!$B$9),"",ROW()-1))} -> 5 | O6: Broken Earth | P6: Lord of Emperors | AL6: {=IF(INDEX(Recommendations!$D:$D,ROW())="","",IF(INDEX(Recommendations!$AJ:$AJ,ROW())=TRUE,"",ROW()))} -> 6
A7: =3 -> 3 | B7: {=IF(TRIM($B$2)<>"",IFERROR(INDEX(_xlfn._xlws.FILTER(Recommendations!$D$2:$D$1086,(Recommendations!$G$2:$G$1086=TRIM($B$2))*(Recommendations!$AJ$2:$AJ$1086<>TRUE)*(Recommendations!$D$2:$D$1086<>BookTracker!$B$9)),ROW()-3),""),IFERROR(INDEX($P:$P,SMALL($N$3:$N$102,ROW()-3)),""))} -> Lord of Emperors | C7: =IF($B7="","",IFERROR(_xlfn.XLOOKUP($B7,Recommendations!$D:$D,Recommendations!$C:$C),"")) -> 8.1486847 | D7: =IF($B7="","",IFERROR(_xlfn.XLOOKUP($B7,Recommendations!$D:$D,Recommendations!$A:$A),"")) -> 44 | E7: =IF($B7="","",IFERROR(_xlfn.XLOOKUP($B7,Recommendations!$D:$D,Recommendations!$E:$E),"")) -> Literary Fantasy | F7: =IF($B7="","",IFERROR(_xlfn.XLOOKUP($B7,Recommendations!$D:$D,Recommendations!$G:$G),"")) -> The Sarantine Mosaic | G7: =IF($B7="","",IFERROR(_xlfn.XLOOKUP($B7,Recommendations!$D:$D,Recommendations!$H:$H),"")) -> 175000 | H7: =IF($B7="","",IFERROR(_xlfn.XLOOKUP($B7,Recommendations!$D:$D,Recommendations!$AJ:$AJ),FALSE)) -> FALSE | I7: =IF($B7="",FALSE,OR($H7=TRUE,$B7=BookTracker!$B$9)) -> FALSE | N7: {=IF(INDEX($P:$P,ROW()-1)="","",IF(OR(IFERROR(_xlfn.XLOOKUP(INDEX($P:$P,ROW()-1),Recommendations!$D:$D,Recommendations!$AJ:$AJ),FALSE)=TRUE,INDEX($P:$P,ROW()-1)=BookTracker!$B$9),"",ROW()-1))} -> 6 | O7: Children of Time | P7: Shadow of the Hegemon | AL7: {=IF(INDEX(Recommendations!$D:$D,ROW())="","",IF(INDEX(Recommendations!$AJ:$AJ,ROW())=TRUE,"",ROW()))} -> 7
A8: =4 -> 4 | B8: {=IF(TRIM($B$2)<>"",IFERROR(INDEX(_xlfn._xlws.FILTER(Recommendations!$D$2:$D$1086,(Recommendations!$G$2:$G$1086=TRIM($B$2))*(Recommendations!$AJ$2:$AJ$1086<>TRUE)*(Recommendations!$D$2:$D$1086<>BookTracker!$B$9)),ROW()-3),""),IFERROR(INDEX($P:$P,SMALL($N$3:$N$102,ROW()-3)),""))} -> Shadow of the Hegemon | C8: =IF($B8="","",IFERROR(_xlfn.XLOOKUP($B8,Recommendations!$D:$D,Recommendations!$C:$C),"")) -> 7.2532681 | D8: =IF($B8="","",IFERROR(_xlfn.XLOOKUP($B8,Recommendations!$D:$D,Recommendations!$A:$A),"")) -> 85 | E8: =IF($B8="","",IFERROR(_xlfn.XLOOKUP($B8,Recommendations!$D:$D,Recommendations!$E:$E),"")) -> Science Fiction (Hard) | F8: =IF($B8="","",IFERROR(_xlfn.XLOOKUP($B8,Recommendations!$D:$D,Recommendations!$G:$G),"")) -> Ender's Shadow | G8: =IF($B8="","",IFERROR(_xlfn.XLOOKUP($B8,Recommendations!$D:$D,Recommendations!$H:$H),"")) -> 95000 | H8: =IF($B8="","",IFERROR(_xlfn.XLOOKUP($B8,Recommendations!$D:$D,Recommendations!$AJ:$AJ),FALSE)) -> FALSE | I8: =IF($B8="",FALSE,OR($H8=TRUE,$B8=BookTracker!$B$9)) -> FALSE | N8: {=IF(INDEX($P:$P,ROW()-1)="","",IF(OR(IFERROR(_xlfn.XLOOKUP(INDEX($P:$P,ROW()-1),Recommendations!$D:$D,Recommendations!$AJ:$AJ),FALSE)=TRUE,INDEX($P:$P,ROW()-1)=BookTracker!$B$9),"",ROW()-1))} -> 7 | O8: Chronicle of the Unhewn Throne | P8: Shadow Puppets | AL8: {=IF(INDEX(Recommendations!$D:$D,ROW())="","",IF(INDEX(Recommendations!$AJ:$AJ,ROW())=TRUE,"",ROW()))} -> 8
A9: =5 -> 5 | B9: {=IF(TRIM($B$2)<>"",IFERROR(INDEX(_xlfn._xlws.FILTER(Recommendations!$D$2:$D$1086,(Recommendations!$G$2:$G$1086=TRIM($B$2))*(Recommendations!$AJ$2:$AJ$1086<>TRUE)*(Recommendations!$D$2:$D$1086<>BookTracker!$B$9)),ROW()-3),""),IFERROR(INDEX($P:$P,SMALL($N$3:$N$102,ROW()-3)),""))} -> Shadow Puppets | C9: =IF($B9="","",IFERROR(_xlfn.XLOOKUP($B9,Recommendations!$D:$D,Recommendations!$C:$C),"")) -> 6.6294837 | D9: =IF($B9="","",IFERROR(_xlfn.XLOOKUP($B9,Recommendations!$D:$D,Recommendations!$A:$A),"")) -> 107 | E9: =IF($B9="","",IFERROR(_xlfn.XLOOKUP($B9,Recommendations!$D:$D,Recommendations!$E:$E),"")) -> Science Fiction (Hard) | F9: =IF($B9="","",IFERROR(_xlfn.XLOOKUP($B9,Recommendations!$D:$D,Recommendations!$G:$G),"")) -> Ender's Shadow | G9: =IF($B9="","",IFERROR(_xlfn.XLOOKUP($B9,Recommendations!$D:$D,Recommendations!$H:$H),"")) -> 99000 | H9: =IF($B9="","",IFERROR(_xlfn.XLOOKUP($B9,Recommendations!$D:$D,Recommendations!$AJ:$AJ),FALSE)) -> FALSE | I9: =IF($B9="",FALSE,OR($H9=TRUE,$B9=BookTracker!$B$9)) -> FALSE | N9: {=IF(INDEX($P:$P,ROW()-1)="","",IF(OR(IFERROR(_xlfn.XLOOKUP(INDEX($P:$P,ROW()-1),Recommendations!$D:$D,Recommendations!$AJ:$AJ),FALSE)=TRUE,INDEX($P:$P,ROW()-1)=BookTracker!$B$9),"",ROW()-1))} -> 8 | O9: Codex Alera | P9: Shadow of the Giant | AL9: {=IF(INDEX(Recommendations!$D:$D,ROW())="","",IF(INDEX(Recommendations!$AJ:$AJ,ROW())=TRUE,"",ROW()))} -> 9
A10: =6 -> 6 | B10: {=IF(TRIM($B$2)<>"",IFERROR(INDEX(_xlfn._xlws.FILTER(Recommendations!$D$2:$D$1086,(Recommendations!$G$2:$G$1086=TRIM($B$2))*(Recommendations!$AJ$2:$AJ$1086<>TRUE)*(Recommendations!$D$2:$D$1086<>BookTracker!$B$9)),ROW()-3),""),IFERROR(INDEX($P:$P,SMALL($N$3:$N$102,ROW()-3)),""))} -> Shadow of the Giant | C10: =IF($B10="","",IFERROR(_xlfn.XLOOKUP($B10,Recommendations!$D:$D,Recommendations!$C:$C),"")) -> 7.2193395 | D10: =IF($B10="","",IFERROR(_xlfn.XLOOKUP($B10,Recommendations!$D:$D,Recommendations!$A:$A),"")) -> 88 | E10: =IF($B10="","",IFERROR(_xlfn.XLOOKUP($B10,Recommendations!$D:$D,Recommendations!$E:$E),"")) -> Science Fiction (Hard) | F10: =IF($B10="","",IFERROR(_xlfn.XLOOKUP($B10,Recommendations!$D:$D,Recommendations!$G:$G),"")) -> Ender's Shadow | G10: =IF($B10="","",IFERROR(_xlfn.XLOOKUP($B10,Recommendations!$D:$D,Recommendations!$H:$H),"")) -> 107000 | H10: =IF($B10="","",IFERROR(_xlfn.XLOOKUP($B10,Recommendations!$D:$D,Recommendations!$AJ:$AJ),FALSE)) -> FALSE | I10: =IF($B10="",FALSE,OR($H10=TRUE,$B10=BookTracker!$B$9)) -> FALSE | N10: {=IF(INDEX($P:$P,ROW()-1)="","",IF(OR(IFERROR(_xlfn.XLOOKUP(INDEX($P:$P,ROW()-1),Recommendations!$D:$D,Recommendations!$AJ:$AJ),FALSE)=TRUE,INDEX($P:$P,ROW()-1)=BookTracker!$B$9),"",ROW()-1))} -> 9 | O10: Conclave of Shadows | P10: The Wise Man's Fear | AL10: {=IF(INDEX(Recommendations!$D:$D,ROW())="","",IF(INDEX(Recommendations!$AJ:$AJ,ROW())=TRUE,"",ROW()))} -> 10
A11: =7 -> 7 | B11: {=IF(TRIM($B$2)<>"",IFERROR(INDEX(_xlfn._xlws.FILTER(Recommendations!$D$2:$D$1086,(Recommendations!$G$2:$G$1086=TRIM($B$2))*(Recommendations!$AJ$2:$AJ$1086<>TRUE)*(Recommendations!$D$2:$D$1086<>BookTracker!$B$9)),ROW()-3),""),IFERROR(INDEX($P:$P,SMALL($N$3:$N$102,ROW()-3)),""))} -> The Wise Man's Fear | C11: =IF($B11="","",IFERROR(_xlfn.XLOOKUP($B11,Recommendations!$D:$D,Recommendations!$C:$C),"")) -> 6.7662303 | D11: =IF($B11="","",IFERROR(_xlfn.XLOOKUP($B11,Recommendations!$D:$D,Recommendations!$A:$A),"")) -> 104 | E11: =IF($B11="","",IFERROR(_xlfn.XLOOKUP($B11,Recommendations!$D:$D,Recommendations!$E:$E),"")) -> Epic Fantasy | F11: =IF($B11="","",IFERROR(_xlfn.XLOOKUP($B11,Recommendations!$D:$D,Recommendations!$G:$G),"")) -> The Kingkiller Chronicle | G11: =IF($B11="","",IFERROR(_xlfn.XLOOKUP($B11,Recommendations!$D:$D,Recommendations!$H:$H),"")) -> 395000 | H11: =IF($B11="","",IFERROR(_xlfn.XLOOKUP($B11,Recommendations!$D:$D,Recommendations!$AJ:$AJ),FALSE)) -> FALSE | I11: =IF($B11="",FALSE,OR($H11=TRUE,$B11=BookTracker!$B$9)) -> FALSE | N11: {=IF(INDEX($P:$P,ROW()-1)="","",IF(OR(IFERROR(_xlfn.XLOOKUP(INDEX($P:$P,ROW()-1),Recommendations!$D:$D,Recommendations!$AJ:$AJ),FALSE)=TRUE,INDEX($P:$P,ROW()-1)=BookTracker!$B$9),"",ROW()-1))} -> 10 | O11: Conqueror | P11: The Obelisk Gate | AL11: {=IF(INDEX(Recommendations!$D:$D,ROW())="","",IF(INDEX(Recommendations!$AJ:$AJ,ROW())=TRUE,"",ROW()))} -> 11
A12: =8 -> 8 | B12: {=IF(TRIM($B$2)<>"",IFERROR(INDEX(_xlfn._xlws.FILTER(Recommendations!$D$2:$D$1086,(Recommendations!$G$2:$G$1086=TRIM($B$2))*(Recommendations!$AJ$2:$AJ$1086<>TRUE)*(Recommendations!$D$2:$D$1086<>BookTracker!$B$9)),ROW()-3),""),IFERROR(INDEX($P:$P,SMALL($N$3:$N$102,ROW()-3)),""))} -> The Obelisk Gate | C12: =IF($B12="","",IFERROR(_xlfn.XLOOKUP($B12,Recommendations!$D:$D,Recommendations!$C:$C),"")) -> 6.9422599 | D12: =IF($B12="","",IFERROR(_xlfn.XLOOKUP($B12,Recommendations!$D:$D,Recommendations!$A:$A),"")) -> 99 | E12: =IF($B12="","",IFERROR(_xlfn.XLOOKUP($B12,Recommendations!$D:$D,Recommendations!$E:$E),"")) -> Science Fiction (Soft) | F12: =IF($B12="","",IFERROR(_xlfn.XLOOKUP($B12,Recommendations!$D:$D,Recommendations!$G:$G),"")) -> Broken Earth | G12: =IF($B12="","",IFERROR(_xlfn.XLOOKUP($B12,Recommendations!$D:$D,Recommendations!$H:$H),"")) -> 110000 | H12: =IF($B12="","",IFERROR(_xlfn.XLOOKUP($B12,Recommendations!$D:$D,Recommendations!$AJ:$AJ),FALSE)) -> FALSE | I12: =IF($B12="",FALSE,OR($H12=TRUE,$B12=BookTracker!$B$9)) -> FALSE | N12: {=IF(INDEX($P:$P,ROW()-1)="","",IF(OR(IFERROR(_xlfn.XLOOKUP(INDEX($P:$P,ROW()-1),Recommendations!$D:$D,Recommendations!$AJ:$AJ),FALSE)=TRUE,INDEX($P:$P,ROW()-1)=BookTracker!$B$9),"",ROW()-1))} -> 11 | O12: Cradle | P12: The Stone Sky | AL12: {=IF(INDEX(Recommendations!$D:$D,ROW())="","",IF(INDEX(Recommendations!$AJ:$AJ,ROW())=TRUE,"",ROW()))} -> 12
A13: =9 -> 9 | B13: {=IF(TRIM($B$2)<>"",IFERROR(INDEX(_xlfn._xlws.FILTER(Recommendations!$D$2:$D$1086,(Recommendations!$G$2:$G$1086=TRIM($B$2))*(Recommendations!$AJ$2:$AJ$1086<>TRUE)*(Recommendations!$D$2:$D$1086<>BookTracker!$B$9)),ROW()-3),""),IFERROR(INDEX($P:$P,SMALL($N$3:$N$102,ROW()-3)),""))} -> The Stone Sky | C13: =IF($B13="","",IFERROR(_xlfn.XLOOKUP($B13,Recommendations!$D:$D,Recommendations!$C:$C),"")) -> 7.4748158 | D13: =IF($B13="","",IFERROR(_xlfn.XLOOKUP($B13,Recommendations!$D:$D,Recommendations!$A:$A),"")) -> 76 | E13: =IF($B13="","",IFERROR(_xlfn.XLOOKUP($B13,Recommendations!$D:$D,Recommendations!$E:$E),"")) -> Science Fiction (Soft) | F13: =IF($B13="","",IFERROR(_xlfn.XLOOKUP($B13,Recommendations!$D:$D,Recommendations!$G:$G),"")) -> Broken Earth | G13: =IF($B13="","",IFERROR(_xlfn.XLOOKUP($B13,Recommendations!$D:$D,Recommendations!$H:$H),"")) -> 110000 | H13: =IF($B13="","",IFERROR(_xlfn.XLOOKUP($B13,Recommendations!$D:$D,Recommendations!$AJ:$AJ),FALSE)) -> FALSE | I13: =IF($B13="",FALSE,OR($H13=TRUE,$B13=BookTracker!$B$9)) -> FALSE | N13: {=IF(INDEX($P:$P,ROW()-1)="","",IF(OR(IFERROR(_xlfn.XLOOKUP(INDEX($P:$P,ROW()-1),Recommendations!$D:$D,Recommendations!$AJ:$AJ),FALSE)=TRUE,INDEX($P:$P,ROW()-1)=BookTracker!$B$9),"",ROW()-1))} -> 12 | O13: Discworld: City Watch | AL13: {=IF(INDEX(Recommendations!$D:$D,ROW())="","",IF(INDEX(Recommendations!$AJ:$AJ,ROW())=TRUE,"",ROW()))} -> 13
A14: =10 -> 10 | B14: {=IF(TRIM($B$2)<>"",IFERROR(INDEX(_xlfn._xlws.FILTER(Recommendations!$D$2:$D$1086,(Recommendations!$G$2:$G$1086=TRIM($B$2))*(Recommendations!$AJ$2:$AJ$1086<>TRUE)*(Recommendations!$D$2:$D$1086<>BookTracker!$B$9)),ROW()-3),""),IFERROR(INDEX($P:$P,SMALL($N$3:$N$102,ROW()-3)),""))} | C14: =IF($B14="","",IFERROR(_xlfn.XLOOKUP($B14,Recommendations!$D:$D,Recommendations!$C:$C),"")) | D14: =IF($B14="","",IFERROR(_xlfn.XLOOKUP($B14,Recommendations!$D:$D,Recommendations!$A:$A),"")) | E14: =IF($B14="","",IFERROR(_xlfn.XLOOKUP($B14,Recommendations!$D:$D,Recommendations!$E:$E),"")) | F14: =IF($B14="","",IFERROR(_xlfn.XLOOKUP($B14,Recommendations!$D:$D,Recommendations!$G:$G),"")) | G14: =IF($B14="","",IFERROR(_xlfn.XLOOKUP($B14,Recommendations!$D:$D,Recommendations!$H:$H),"")) | H14: =IF($B14="","",IFERROR(_xlfn.XLOOKUP($B14,Recommendations!$D:$D,Recommendations!$AJ:$AJ),FALSE)) | I14: =IF($B14="",FALSE,OR($H14=TRUE,$B14=BookTracker!$B$9)) -> FALSE | N14: {=IF(INDEX($P:$P,ROW()-1)="","",IF(OR(IFERROR(_xlfn.XLOOKUP(INDEX($P:$P,ROW()-1),Recommendations!$D:$D,Recommendations!$AJ:$AJ),FALSE)=TRUE,INDEX($P:$P,ROW()-1)=BookTracker!$B$9),"",ROW()-1))} | O14: Discworld: Death | AL14: {=IF(INDEX(Recommendations!$D:$D,ROW())="","",IF(INDEX(Recommendations!$AJ:$AJ,ROW())=TRUE,"",ROW()))} -> 14
A15: =11 -> 11 | B15: {=IF(TRIM($B$2)<>"",IFERROR(INDEX(_xlfn._xlws.FILTER(Recommendations!$D$2:$D$1086,(Recommendations!$G$2:$G$1086=TRIM($B$2))*(Recommendations!$AJ$2:$AJ$1086<>TRUE)*(Recommendations!$D$2:$D$1086<>BookTracker!$B$9)),ROW()-3),""),IFERROR(INDEX($P:$P,SMALL($N$3:$N$102,ROW()-3)),""))} | C15: =IF($B15="","",IFERROR(_xlfn.XLOOKUP($B15,Recommendations!$D:$D,Recommendations!$C:$C),"")) | D15: =IF($B15="","",IFERROR(_xlfn.XLOOKUP($B15,Recommendations!$D:$D,Recommendations!$A:$A),"")) | E15: =IF($B15="","",IFERROR(_xlfn.XLOOKUP($B15,Recommendations!$D:$D,Recommendations!$E:$E),"")) | F15: =IF($B15="","",IFERROR(_xlfn.XLOOKUP($B15,Recommendations!$D:$D,Recommendations!$G:$G),"")) | G15: =IF($B15="","",IFERROR(_xlfn.XLOOKUP($B15,Recommendations!$D:$D,Recommendations!$H:$H),"")) | H15: =IF($B15="","",IFERROR(_xlfn.XLOOKUP($B15,Recommendations!$D:$D,Recommendations!$AJ:$AJ),FALSE)) | I15: =IF($B15="",FALSE,OR($H15=TRUE,$B15=BookTracker!$B$9)) -> FALSE | N15: {=IF(INDEX($P:$P,ROW()-1)="","",IF(OR(IFERROR(_xlfn.XLOOKUP(INDEX($P:$P,ROW()-1),Recommendations!$D:$D,Recommendations!$AJ:$AJ),FALSE)=TRUE,INDEX($P:$P,ROW()-1)=BookTracker!$B$9),"",ROW()-1))} | O15: Discworld: Moist von Lipwig | AL15: {=IF(INDEX(Recommendations!$D:$D,ROW())="","",IF(INDEX(Recommendations!$AJ:$AJ,ROW())=TRUE,"",ROW()))} -> 15
A16: =12 -> 12 | B16: {=IF(TRIM($B$2)<>"",IFERROR(INDEX(_xlfn._xlws.FILTER(Recommendations!$D$2:$D$1086,(Recommendations!$G$2:$G$1086=TRIM($B$2))*(Recommendations!$AJ$2:$AJ$1086<>TRUE)*(Recommendations!$D$2:$D$1086<>BookTracker!$B$9)),ROW()-3),""),IFERROR(INDEX($P:$P,SMALL($N$3:$N$102,ROW()-3)),""))} | C16: =IF($B16="","",IFERROR(_xlfn.XLOOKUP($B16,Recommendations!$D:$D,Recommendations!$C:$C),"")) | D16: =IF($B16="","",IFERROR(_xlfn.XLOOKUP($B16,Recommendations!$D:$D,Recommendations!$A:$A),"")) | E16: =IF($B16="","",IFERROR(_xlfn.XLOOKUP($B16,Recommendations!$D:$D,Recommendations!$E:$E),"")) | F16: =IF($B16="","",IFERROR(_xlfn.XLOOKUP($B16,Recommendations!$D:$D,Recommendations!$G:$G),"")) | G16: =IF($B16="","",IFERROR(_xlfn.XLOOKUP($B16,Recommendations!$D:$D,Recommendations!$H:$H),"")) | H16: =IF($B16="","",IFERROR(_xlfn.XLOOKUP($B16,Recommendations!$D:$D,Recommendations!$AJ:$AJ),FALSE)) | I16: =IF($B16="",FALSE,OR($H16=TRUE,$B16=BookTracker!$B$9)) -> FALSE | N16: {=IF(INDEX($P:$P,ROW()-1)="","",IF(OR(IFERROR(_xlfn.XLOOKUP(INDEX($P:$P,ROW()-1),Recommendations!$D:$D,Recommendations!$AJ:$AJ),FALSE)=TRUE,INDEX($P:$P,ROW()-1)=BookTracker!$B$9),"",ROW()-1))} | O16: Discworld: Rincewind | AL16: {=IF(INDEX(Recommendations!$D:$D,ROW())="","",IF(INDEX(Recommendations!$AJ:$AJ,ROW())=TRUE,"",ROW()))} -> 16
A17: =13 -> 13 | B17: {=IF(TRIM($B$2)<>"",IFERROR(INDEX(_xlfn._xlws.FILTER(Recommendations!$D$2:$D$1086,(Recommendations!$G$2:$G$1086=TRIM($B$2))*(Recommendations!$AJ$2:$AJ$1086<>TRUE)*(Recommendations!$D$2:$D$1086<>BookTracker!$B$9)),ROW()-3),""),IFERROR(INDEX($P:$P,SMALL($N$3:$N$102,ROW()-3)),""))} | C17: =IF($B17="","",IFERROR(_xlfn.XLOOKUP($B17,Recommendations!$D:$D,Recommendations!$C:$C),"")) | D17: =IF($B17="","",IFERROR(_xlfn.XLOOKUP($B17,Recommendations!$D:$D,Recommendations!$A:$A),"")) | E17: =IF($B17="","",IFERROR(_xlfn.XLOOKUP($B17,Recommendations!$D:$D,Recommendations!$E:$E),"")) | F17: =IF($B17="","",IFERROR(_xlfn.XLOOKUP($B17,Recommendations!$D:$D,Recommendations!$G:$G),"")) | G17: =IF($B17="","",IFERROR(_xlfn.XLOOKUP($B17,Recommendations!$D:$D,Recommendations!$H:$H),"")) | H17: =IF($B17="","",IFERROR(_xlfn.XLOOKUP($B17,Recommendations!$D:$D,Recommendations!$AJ:$AJ),FALSE)) | I17: =IF($B17="",FALSE,OR($H17=TRUE,$B17=BookTracker!$B$9)) -> FALSE | N17: {=IF(INDEX($P:$P,ROW()-1)="","",IF(OR(IFERROR(_xlfn.XLOOKUP(INDEX($P:$P,ROW()-1),Recommendations!$D:$D,Recommendations!$AJ:$AJ),FALSE)=TRUE,INDEX($P:$P,ROW()-1)=BookTracker!$B$9),"",ROW()-1))} | O17: Discworld: Standalone | AL17: {=IF(INDEX(Recommendations!$D:$D,ROW())="","",IF(INDEX(Recommendations!$AJ:$AJ,ROW())=TRUE,"",ROW()))} -> 17
A18: =14 -> 14 | B18: {=IF(TRIM($B$2)<>"",IFERROR(INDEX(_xlfn._xlws.FILTER(Recommendations!$D$2:$D$1086,(Recommendations!$G$2:$G$1086=TRIM($B$2))*(Recommendations!$AJ$2:$AJ$1086<>TRUE)*(Recommendations!$D$2:$D$1086<>BookTracker!$B$9)),ROW()-3),""),IFERROR(INDEX($P:$P,SMALL($N$3:$N$102,ROW()-3)),""))} | C18: =IF($B18="","",IFERROR(_xlfn.XLOOKUP($B18,Recommendations!$D:$D,Recommendations!$C:$C),"")) | D18: =IF($B18="","",IFERROR(_xlfn.XLOOKUP($B18,Recommendations!$D:$D,Recommendations!$A:$A),"")) | E18: =IF($B18="","",IFERROR(_xlfn.XLOOKUP($B18,Recommendations!$D:$D,Recommendations!$E:$E),"")) | F18: =IF($B18="","",IFERROR(_xlfn.XLOOKUP($B18,Recommendations!$D:$D,Recommendations!$G:$G),"")) | G18: =IF($B18="","",IFERROR(_xlfn.XLOOKUP($B18,Recommendations!$D:$D,Recommendations!$H:$H),"")) | H18: =IF($B18="","",IFERROR(_xlfn.XLOOKUP($B18,Recommendations!$D:$D,Recommendations!$AJ:$AJ),FALSE)) | I18: =IF($B18="",FALSE,OR($H18=TRUE,$B18=BookTracker!$B$9)) -> FALSE | N18: {=IF(INDEX($P:$P,ROW()-1)="","",IF(OR(IFERROR(_xlfn.XLOOKUP(INDEX($P:$P,ROW()-1),Recommendations!$D:$D,Recommendations!$AJ:$AJ),FALSE)=TRUE,INDEX($P:$P,ROW()-1)=BookTracker!$B$9),"",ROW()-1))} | O18: Discworld: Tiffany Aching | AL18: {=IF(INDEX(Recommendations!$D:$D,ROW())="","",IF(INDEX(Recommendations!$AJ:$AJ,ROW())=TRUE,"",ROW()))} -> 18
A19: =15 -> 15 | B19: {=IF(TRIM($B$2)<>"",IFERROR(INDEX(_xlfn._xlws.FILTER(Recommendations!$D$2:$D$1086,(Recommendations!$G$2:$G$1086=TRIM($B$2))*(Recommendations!$AJ$2:$AJ$1086<>TRUE)*(Recommendations!$D$2:$D$1086<>BookTracker!$B$9)),ROW()-3),""),IFERROR(INDEX($P:$P,SMALL($N$3:$N$102,ROW()-3)),""))} | C19: =IF($B19="","",IFERROR(_xlfn.XLOOKUP($B19,Recommendations!$D:$D,Recommendations!$C:$C),"")) | D19: =IF($B19="","",IFERROR(_xlfn.XLOOKUP($B19,Recommendations!$D:$D,Recommendations!$A:$A),"")) | E19: =IF($B19="","",IFERROR(_xlfn.XLOOKUP($B19,Recommendations!$D:$D,Recommendations!$E:$E),"")) | F19: =IF($B19="","",IFERROR(_xlfn.XLOOKUP($B19,Recommendations!$D:$D,Recommendations!$G:$G),"")) | G19: =IF($B19="","",IFERROR(_xlfn.XLOOKUP($B19,Recommendations!$D:$D,Recommendations!$H:$H),"")) | H19: =IF($B19="","",IFERROR(_xlfn.XLOOKUP($B19,Recommendations!$D:$D,Recommendations!$AJ:$AJ),FALSE)) | I19: =IF($B19="",FALSE,OR($H19=TRUE,$B19=BookTracker!$B$9)) -> FALSE | N19: {=IF(INDEX($P:$P,ROW()-1)="","",IF(OR(IFERROR(_xlfn.XLOOKUP(INDEX($P:$P,ROW()-1),Recommendations!$D:$D,Recommendations!$AJ:$AJ),FALSE)=TRUE,INDEX($P:$P,ROW()-1)=BookTracker!$B$9),"",ROW()-1))} | O19: Discworld: Witches | AL19: {=IF(INDEX(Recommendations!$D:$D,ROW())="","",IF(INDEX(Recommendations!$AJ:$AJ,ROW())=TRUE,"",ROW()))} -> 19
A20: =16 -> 16 | B20: {=IF(TRIM($B$2)<>"",IFERROR(INDEX(_xlfn._xlws.FILTER(Recommendations!$D$2:$D$1086,(Recommendations!$G$2:$G$1086=TRIM($B$2))*(Recommendations!$AJ$2:$AJ$1086<>TRUE)*(Recommendations!$D$2:$D$1086<>BookTracker!$B$9)),ROW()-3),""),IFERROR(INDEX($P:$P,SMALL($N$3:$N$102,ROW()-3)),""))} | C20: =IF($B20="","",IFERROR(_xlfn.XLOOKUP($B20,Recommendations!$D:$D,Recommendations!$C:$C),"")) | D20: =IF($B20="","",IFERROR(_xlfn.XLOOKUP($B20,Recommendations!$D:$D,Recommendations!$A:$A),"")) | E20: =IF($B20="","",IFERROR(_xlfn.XLOOKUP($B20,Recommendations!$D:$D,Recommendations!$E:$E),"")) | F20: =IF($B20="","",IFERROR(_xlfn.XLOOKUP($B20,Recommendations!$D:$D,Recommendations!$G:$G),"")) | G20: =IF($B20="","",IFERROR(_xlfn.XLOOKUP($B20,Recommendations!$D:$D,Recommendations!$H:$H),"")) | H20: =IF($B20="","",IFERROR(_xlfn.XLOOKUP($B20,Recommendations!$D:$D,Recommendations!$AJ:$AJ),FALSE)) | I20: =IF($B20="",FALSE,OR($H20=TRUE,$B20=BookTracker!$B$9)) -> FALSE | N20: {=IF(INDEX($P:$P,ROW()-1)="","",IF(OR(IFERROR(_xlfn.XLOOKUP(INDEX($P:$P,ROW()-1),Recommendations!$D:$D,Recommendations!$AJ:$AJ),FALSE)=TRUE,INDEX($P:$P,ROW()-1)=BookTracker!$B$9),"",ROW()-1))} | O20: Drenai Saga | AL20: {=IF(INDEX(Recommendations!$D:$D,ROW())="","",IF(INDEX(Recommendations!$AJ:$AJ,ROW())=TRUE,"",ROW()))} -> 20
N21: {=IF(INDEX($P:$P,ROW()-1)="","",IF(OR(IFERROR(_xlfn.XLOOKUP(INDEX($P:$P,ROW()-1),Recommendations!$D:$D,Recommendations!$AJ:$AJ),FALSE)=TRUE,INDEX($P:$P,ROW()-1)=BookTracker!$B$9),"",ROW()-1))} | O21: Dune | AL21: {=IF(INDEX(Recommendations!$D:$D,ROW())="","",IF(INDEX(Recommendations!$AJ:$AJ,ROW())=TRUE,"",ROW()))} -> 21
B22: 🎭 MOOD WEIGHTS (0-5 Scale, Combinable) | N22: {=IF(INDEX($P:$P,ROW()-1)="","",IF(OR(IFERROR(_xlfn.XLOOKUP(INDEX($P:$P,ROW()-1),Recommendations!$D:$D,Recommendations!$AJ:$AJ),FALSE)=TRUE,INDEX($P:$P,ROW()-1)=BookTracker!$B$9),"",ROW()-1))} | O22: Earthsea Cycle | AL22: {=IF(INDEX(Recommendations!$D:$D,ROW())="","",IF(INDEX(Recommendations!$AJ:$AJ,ROW())=TRUE,"",ROW()))} -> 22
A23: Mood | B23: Weight (0-5) | C23: Components Weighted | N23: {=IF(INDEX($P:$P,ROW()-1)="","",IF(OR(IFERROR(_xlfn.XLOOKUP(INDEX($P:$P,ROW()-1),Recommendations!$D:$D,Recommendations!$AJ:$AJ),FALSE)=TRUE,INDEX($P:$P,ROW()-1)=BookTracker!$B$9),"",ROW()-1))} | O23: Eisenhorn | AL23: {=IF(INDEX(Recommendations!$D:$D,ROW())="","",IF(INDEX(Recommendations!$AJ:$AJ,ROW())=TRUE,"",ROW()))} -> 23
A24: Action-Heavy | B24: 0 | C24: Action, Plot, Entertainment | N24: {=IF(INDEX($P:$P,ROW()-1)="","",IF(OR(IFERROR(_xlfn.XLOOKUP(INDEX($P:$P,ROW()-1),Recommendations!$D:$D,Recommendations!$AJ:$AJ),FALSE)=TRUE,INDEX($P:$P,ROW()-1)=BookTracker!$B$9),"",ROW()-1))} | O24: Ender's Shadow | AL24: {=IF(INDEX(Recommendations!$D:$D,ROW())="","",IF(INDEX(Recommendations!$AJ:$AJ,ROW())=TRUE,"",ROW()))} -> 24
A25: Theme-Heavy | B25: 0 | C25: Insights, Philosophizing, Thought-Provokingness | N25: {=IF(INDEX($P:$P,ROW()-1)="","",IF(OR(IFERROR(_xlfn.XLOOKUP(INDEX($P:$P,ROW()-1),Recommendations!$D:$D,Recommendations!$AJ:$AJ),FALSE)=TRUE,INDEX($P:$P,ROW()-1)=BookTracker!$B$9),"",ROW()-1))} | O25: Firefall | AL25: {=IF(INDEX(Recommendations!$D:$D,ROW())="","",IF(INDEX(Recommendations!$AJ:$AJ,ROW())=TRUE,"",ROW()))} -> 25
A26: Emotion-Heavy | B26: 0 | C26: Emotional Impact, Depth, Character Avg | N26: {=IF(INDEX($P:$P,ROW()-1)="","",IF(OR(IFERROR(_xlfn.XLOOKUP(INDEX($P:$P,ROW()-1),Recommendations!$D:$D,Recommendations!$AJ:$AJ),FALSE)=TRUE,INDEX($P:$P,ROW()-1)=BookTracker!$B$9),"",ROW()-1))} | O26: Foundation | AL26: {=IF(INDEX(Recommendations!$D:$D,ROW())="","",IF(INDEX(Recommendations!$AJ:$AJ,ROW())=TRUE,"",ROW()))} -> 26
A27: Immersion-Heavy | B27: 0 | C27: WB Depth, WB Originality, Prose, Phraseology | N27: {=IF(INDEX($P:$P,ROW()-1)="","",IF(OR(IFERROR(_xlfn.XLOOKUP(INDEX($P:$P,ROW()-1),Recommendations!$D:$D,Recommendations!$AJ:$AJ),FALSE)=TRUE,INDEX($P:$P,ROW()-1)=BookTracker!$B$9),"",ROW()-1))} | O27: Gentleman Bastards | AL27: {=IF(INDEX(Recommendations!$D:$D,ROW())="","",IF(INDEX(Recommendations!$AJ:$AJ,ROW())=TRUE,"",ROW()))} -> 27
A28: Story-Heavy | B28: 0 | C28: Plot, Ending, Entertainment, Pacing | N28: {=IF(INDEX($P:$P,ROW()-1)="","",IF(OR(IFERROR(_xlfn.XLOOKUP(INDEX($P:$P,ROW()-1),Recommendations!$D:$D,Recommendations!$AJ:$AJ),FALSE)=TRUE,INDEX($P:$P,ROW()-1)=BookTracker!$B$9),"",ROW()-1))} | O28: Gilead | AL28: {=IF(INDEX(Recommendations!$D:$D,ROW())="","",IF(INDEX(Recommendations!$AJ:$AJ,ROW())=TRUE,"",ROW()))} -> 28
A29: Character-Heavy | B29: 0 | C29: Depth, Motivations, Multi-Dimensionality | N29: {=IF(INDEX($P:$P,ROW()-1)="","",IF(OR(IFERROR(_xlfn.XLOOKUP(INDEX($P:$P,ROW()-1),Recommendations!$D:$D,Recommendations!$AJ:$AJ),FALSE)=TRUE,INDEX($P:$P,ROW()-1)=BookTracker!$B$9),"",ROW()-1))} | O29: Gormenghast | AL29: {=IF(INDEX(Recommendations!$D:$D,ROW())="","",IF(INDEX(Recommendations!$AJ:$AJ,ROW())=TRUE,"",ROW()))} -> 29
